Workbook

Sheet Sheet1
A1: Date | B1: Members | C1: Premiums Collected | D1: Claims Incurred | E1: Administrative Expenses
A2: 36526 | B2: 2147 | C2: =B2*RANDBETWEEN(400,500)/30 -> 29700.167 | D2: =C2*RANDBETWEEN(85,95)/100 -> 27621.155 | E2: =C2*RANDBETWEEN(5,10)/100 -> 2673.015
A3: =A2+1 -> 36527 | B3: =ROUND(B2*(1+RANDBETWEEN(1,5)/10000),0) -> 2147 | C3: =(C2/B2)*(1+RANDBETWEEN(1,3)/100/360)*B3 -> 29702.642 | D3: =C3*RANDBETWEEN(85,95)/100 -> 26138.325 | E3: =C3*RANDBETWEEN(5,10)/100 -> 2970.2642
A4: =A3+1 -> 36528 | B4: =ROUND(B3*(1+RANDBETWEEN(1,5)/10000),0) -> 2148 | C4: =(C3/B3)*(1+RANDBETWEEN(1,3)/100/360)*B4 -> 29718.953 | D4: =C4*RANDBETWEEN(85,95)/100 -> 27638.626 | E4: =C4*RANDBETWEEN(5,10)/100 -> 1783.1372
A5: =A4+1 -> 36529 | B5: =ROUND(B4*(1+RANDBETWEEN(1,5)/10000),0) -> 2149 | C5: =(C4/B4)*(1+RANDBETWEEN(1,3)/100/360)*B5 -> 29735.266 | D5: =C5*RANDBETWEEN(85,95)/100 -> 27059.092 | E5: =C5*RANDBETWEEN(5,10)/100 -> 2378.8213
A6: =A5+1 -> 36530 | B6: =ROUND(B5*(1+RANDBETWEEN(1,5)/10000),0) -> 2150 | C6: =(C5/B5)*(1+RANDBETWEEN(1,3)/100/360)*B6 -> 29750.755 | D6: =C6*RANDBETWEEN(85,95)/100 -> 25288.142 | E6: =C6*RANDBETWEEN(5,10)/100 -> 2677.568
A7: =A6+1 -> 36531 | B7: =ROUND(B6*(1+RANDBETWEEN(1,5)/10000),0) -> 2151 | C7: =(C6/B6)*(1+RANDBETWEEN(1,3)/100/360)*B7 -> 29765.42 | D7: =C7*RANDBETWEEN(85,95)/100 -> 27979.495 | E7: =C7*RANDBETWEEN(5,10)/100 -> 2381.2336
A8: =A7+1 -> 36532 | B8: =ROUND(B7*(1+RANDBETWEEN(1,5)/10000),0) -> 2151 | C8: =(C7/B7)*(1+RANDBETWEEN(1,3)/100/360)*B8 -> 29767.073 | D8: =C8*RANDBETWEEN(85,95)/100 -> 25897.354 | E8: =C8*RANDBETWEEN(5,10)/100 -> 2679.0366
A9: =A8+1 -> 36533 | B9: =ROUND(B8*(1+RANDBETWEEN(1,5)/10000),0) -> 2151 | C9: =(C8/B8)*(1+RANDBETWEEN(1,3)/100/360)*B9 -> 29769.554 | D9: =C9*RANDBETWEEN(85,95)/100 -> 25899.512 | E9: =C9*RANDBETWEEN(5,10)/100 -> 1488.4777
A10: =A9+1 -> 36534 | B10: =ROUND(B9*(1+RANDBETWEEN(1,5)/10000),0) -> 2152 | C10: =(C9/B9)*(1+RANDBETWEEN(1,3)/100/360)*B10 -> 29785.049 | D10: =C10*RANDBETWEEN(85,95)/100 -> 26806.544 | E10: =C10*RANDBETWEEN(5,10)/100 -> 2382.8039
A11: =A10+1 -> 36535 | B11: =ROUND(B10*(1+RANDBETWEEN(1,5)/10000),0) -> 2152 | C11: =(C10/B10)*(1+RANDBETWEEN(1,3)/100/360)*B11 -> 29786.703 | D11: =C11*RANDBETWEEN(85,95)/100 -> 25616.565 | E11: =C11*RANDBETWEEN(5,10)/100 -> 2382.9363
A12: =A11+1 -> 36536 | B12: =ROUND(B11*(1+RANDBETWEEN(1,5)/10000),0) -> 2153 | C12: =(C11/B11)*(1+RANDBETWEEN(1,3)/100/360)*B12 -> 29803.028 | D12: =C12*RANDBETWEEN(85,95)/100 -> 26226.665 | E12: =C12*RANDBETWEEN(5,10)/100 -> 2682.2725
A13: =A12+1 -> 36537 | B13: =ROUND(B12*(1+RANDBETWEEN(1,5)/10000),0) -> 2153 | C13: =(C12/B12)*(1+RANDBETWEEN(1,3)/100/360)*B13 -> 29803.856 | D13: =C13*RANDBETWEEN(85,95)/100 -> 28313.663 | E13: =C13*RANDBETWEEN(5,10)/100 -> 2980.3856
A14: =A13+1 -> 36538 | B14: =ROUND(B13*(1+RANDBETWEEN(1,5)/10000),0) -> 2153 | C14: =(C13/B13)*(1+RANDBETWEEN(1,3)/100/360)*B14 -> 29804.684 | D14: =C14*RANDBETWEEN(85,95)/100 -> 25632.028 | E14: =C14*RANDBETWEEN(5,10)/100 -> 1490.2342
... A9498: =A9497+1 -> 46022 | B9498: =ROUND(B9497*(1+RANDBETWEEN(1,5)/10000),0) -> 34199 | C9498: =(C9497/B9497)*(1+RANDBETWEEN(1,3)/100/360)*B9498 -> 802701.25 | D9498: =C9498*RANDBETWEEN(85,95)/100 -> 730458.14 | E9498: =C9498*RANDBETWEEN(5,10)/100 -> 72243.112

Sheet Insurance_Corp_Financials_CSV (
A1: Date | B1: Members | C1: Premiums Collected | D1: Claims Incurred | E1: Administrative Expenses
A2: 36526 | B2: 2147 | C2: 31059.933 | D2: 29196.337 | E2: 2484.7947
A3: =A2+1 -> 36527 | B3: 2147 | C3: 31061.659 | D3: 26713.027 | E3: 1553.0829
A4: =A3+1 -> 36528 | B4: 2148 | C4: 31076.99 | D4: 29212.37 | E4: 2796.9291
A5: =A4+1 -> 36529 | B5: 2149 | C5: 31092.321 | D5: 26739.396 | E5: 2487.3857
A6: =A5+1 -> 36530 | B6: 2149 | C6: 31094.048 | D6: 26740.882 | E6: 2798.4644
A7: =A6+1 -> 36531 | B7: 2149 | C7: 31096.64 | D7: 29230.841 | E7: 2798.6976
A8: =A7+1 -> 36532 | B8: 2149 | C8: 31097.503 | D8: 28298.728 | E8: 1865.8502
A9: =A8+1 -> 36533 | B9: 2150 | C9: 31113.703 | D9: 28935.743 | E9: 1866.8222
A10: =A9+1 -> 36534 | B10: 2150 | C10: 31114.567 | D10: 26758.527 | E10: 2178.0197
A11: =A10+1 -> 36535 | B11: 2151 | C11: 31131.633 | D11: 26773.204 | E11: 2490.5306
A12: =A11+1 -> 36536 | B12: 2152 | C12: 31148.701 | D12: 28345.318 | E12: 2491.8961
A13: =A12+1 -> 36537 | B13: 2152 | C13: 31151.297 | D13: 26790.116 | E13: 2492.1038
A14: =A13+1 -> 36538 | B14: 2153 | C14: 31166.638 | D14: 27426.642 | E14: 2181.6647
... A9498: =A9497+1 -> 46022 | B9498: 35712 | C9498: 878979.05 | D9498: 747132.19 | E9498: 43948.952

Sheet Project Intro
A1: INSURANCE CORP FINANCIALS PROJECT
B2: Task 1: Data Import
B3: *Successfully download and import the "Insurance Corp Financials CSV" file into this spreadsheet, and reformat it into the form shown in the Task1 tab.
B4: Task 2: Analysis Table
B5: *Reformat your data from the Task1 tab into the format shown in Columns B-F of the Task2 tab. Sum all premiums, claims, and expenses in Cells D1:F1 respectively to aid you as a check for this task.
B6: *Devise a method by which to complete each cell in the "Summary" table in Columns I-Q in accordance with video instructions. Add formatting to the table design.
B7: Task 3: Lookup Tool
B8: *Your results from Task2 will be automatically carried over into Columns A-J of Task3. Reformat this table as you did for Task2.
B9: *Design a "Lookup Tool" in Columns L-P. This should look up results for any YYYYMM in Column A provided into cells L3:L14 and any metric from cells B2:J2 provided into cells M2:P2. Restrict user inputs accordingly for L3:L14 and M2:P2.
B10: *A full table of results from the lookups should populate cells M3:P14. You may use any YYYYMM inputs and cell M2:P2 inputs to complete the table.
B11: Task 4: Forecasting
B12: *Set your Lookup Tool from Task3 to have the inputs shown for the YYYYMMs given in cells A3:A14 and B2:E2 of Task4. Cells B3:E14 in Task4 will read in your results.
B13: *Use Columns F-I as indicators of whether or not to apply trend factors to these values. Use a LOOKUP formula to populate Columns J-M with either a trend factor from the Trend Factors Table tab or a default value of 1.
... B20: Similarly, use conditional formatting to highlight the Bottom 10% of values as the "best projections" and highlight these in green.
A21: CONGRATULATIONS! SUCCESSFUL COMPLETION OF THIS PROJECT INDICATES YOU POSSESS FUNDAMENTAL ABILITIES EXPECTED OF AN ACTUARIAL ANALYST!

Sheet Task1 - Data Import
A1: Date | B1: Members | C1: Premiums Collected | D1: Claims Incurred | E1: Administrative Expenses
A2: 36526 | B2: 2147 | C2: 31059.933 | D2: 29196.337 | E2: 2484.7947
A3: =A2+1 -> 36527 | B3: 2147 | C3: 31061.659 | D3: 26713.027 | E3: 1553.0829
A4: =A3+1 -> 36528 | B4: 2148 | C4: 31076.99 | D4: 29212.37 | E4: 2796.9291
A5: =A4+1 -> 36529 | B5: 2149 | C5: 31092.321 | D5: 26739.396 | E5: 2487.3857
A6: =A5+1 -> 36530 | B6: 2149 | C6: 31094.048 | D6: 26740.882 | E6: 2798.4644
A7: =A6+1 -> 36531 | B7: 2149 | C7: 31096.64 | D7: 29230.841 | E7: 2798.6976
A8: =A7+1 -> 36532 | B8: 2149 | C8: 31097.503 | D8: 28298.728 | E8: 1865.8502
A9: =A8+1 -> 36533 | B9: 2150 | C9: 31113.703 | D9: 28935.743 | E9: 1866.8222
A10: =A9+1 -> 36534 | B10: 2150 | C10: 31114.567 | D10: 26758.527 | E10: 2178.0197
A11: =A10+1 -> 36535 | B11: 2151 | C11: 31131.633 | D11: 26773.204 | E11: 2490.5306
A12: =A11+1 -> 36536 | B12: 2152 | C12: 31148.701 | D12: 28345.318 | E12: 2491.8961
A13: =A12+1 -> 36537 | B13: 2152 | C13: 31151.297 | D13: 26790.116 | E13: 2492.1038
A14: =A13+1 -> 36538 | B14: 2153 | C14: 31166.638 | D14: 27426.642 | E14: 2181.6647
... A9498: =A9497+1 -> 46022 | B9498: 35712 | C9498: 878979.05 | D9498: 747132.19 | E9498: 43948.952

Sheet Task 2 - Analysis Table
A1: DOWNLOADED DATA | D1: =SUM(D3:D9499) -> 2.3956794e+09 | E1: =SUM(E3:E9499) -> 2.1554843e+09 | F1: =SUM(F3:F9499) -> 1.8013468e+08 | G1: =D1-E1-F1 -> 60060355 | H1: SUMMARY | I1: AVERAGE | J1: TOTALS BY CATEGORY | N1: PER MEMBER
B2: Date | C2: Members | D2: Premiums | E2: Claims | F2: Expenses | H2: YYYYMM | I2: Members | J2: Premiums | K2: Claims | L2: Expenses | M2: Profits | N2: Prem/Mem | O2: Claims/Mem | P2: Exp/Mem | Q2: Profits/Mem
B3: 36526 | C3: 2147 | D3: 31059.933 | E3: 29196.337 | F3: 2484.7947 | G3: =YEAR(B3)&IF(MONTH(B3)<10,0&MONTH(B3),MONTH(B3)) -> 200001 | H3: 200001 | I3: =AVERAGEIFS(C$3:C$9499,$G$3:$G$9499,$H3) -> 2154.0968 | J3: =SUMIFS(D$3:D$9499,$G$3:$G$9499,$H3) -> 966792.45 | K3: =SUMIFS(E$3:E$9499,$G$3:$G$9499,$H3) -> 863873.17 | L3: =SUMIFS(F$3:F$9499,$G$3:$G$9499,$H3) -> 72985.325 | M3: =J3-K3-L3 -> 29933.956 | N3: =J3/$I3 -> 448.8157 | O3: =K3/$I3 -> 401.03731 | P3: =L3/$I3 -> 33.882101 | Q3: =N3-O3-P3 -> 13.896291
B4: =B3+1 -> 36527 | C4: 2147 | D4: 31061.659 | E4: 26713.027 | F4: 1553.0829 | G4: =YEAR(B4)&IF(MONTH(B4)<10,0&MONTH(B4),MONTH(B4)) -> 200001 | H4: 200002 | I4: =AVERAGEIFS(C$3:C$9499,$G$3:$G$9499,$H4) -> 2171.4483 | J4: =SUMIFS(D$3:D$9499,$G$3:$G$9499,$H4) -> 913328.62 | K4: =SUMIFS(E$3:E$9499,$G$3:$G$9499,$H4) -> 814119.13 | L4: =SUMIFS(F$3:F$9499,$G$3:$G$9499,$H4) -> 62677.37 | M4: =J4-K4-L4 -> 36532.124 | N4: =J4/$I4 -> 420.60805 | O4: =K4/$I4 -> 374.91988 | P4: =L4/$I4 -> 28.864316 | Q4: =N4-O4-P4 -> 16.823852
B5: =B4+1 -> 36528 | C5: 2148 | D5: 31076.99 | E5: 29212.37 | F5: 2796.9291 | G5: =YEAR(B5)&IF(MONTH(B5)<10,0&MONTH(B5),MONTH(B5)) -> 200001 | H5: 200003 | I5: =AVERAGEIFS(C$3:C$9499,$G$3:$G$9499,$H5) -> 2187.7742 | J5: =SUMIFS(D$3:D$9499,$G$3:$G$9499,$H5) -> 985298.95 | K5: =SUMIFS(E$3:E$9499,$G$3:$G$9499,$H5) -> 881036.07 | L5: =SUMIFS(F$3:F$9499,$G$3:$G$9499,$H5) -> 76594.593 | M5: =J5-K5-L5 -> 27668.288 | N5: =J5/$I5 -> 450.36592 | O5: =K5/$I5 -> 402.70887 | P5: =L5/$I5 -> 35.010283 | Q5: =N5-O5-P5 -> 12.646775
B6: =B5+1 -> 36529 | C6: 2149 | D6: 31092.321 | E6: 26739.396 | F6: 2487.3857 | G6: =YEAR(B6)&IF(MONTH(B6)<10,0&MONTH(B6),MONTH(B6)) -> 200001 | H6: 200004 | I6: =AVERAGEIFS(C$3:C$9499,$G$3:$G$9499,$H6) -> 2202.5333 | J6: =SUMIFS(D$3:D$9499,$G$3:$G$9499,$H6) -> 961495.21 | K6: =SUMIFS(E$3:E$9499,$G$3:$G$9499,$H6) -> 868864.78 | L6: =SUMIFS(F$3:F$9499,$G$3:$G$9499,$H6) -> 70190.545 | M6: =J6-K6-L6 -> 22439.88 | N6: =J6/$I6 -> 436.54059 | O6: =K6/$I6 -> 394.48428 | P6: =L6/$I6 -> 31.868097 | Q6: =N6-O6-P6 -> 10.188214
B7: =B6+1 -> 36530 | C7: 2149 | D7: 31094.048 | E7: 26740.882 | F7: 2798.4644 | G7: =YEAR(B7)&IF(MONTH(B7)<10,0&MONTH(B7),MONTH(B7)) -> 200001 | H7: 200005 | I7: =AVERAGEIFS(C$3:C$9499,$G$3:$G$9499,$H7) -> 2219.6774 | J7: =SUMIFS(D$3:D$9499,$G$3:$G$9499,$H7) -> 1003032.5 | K7: =SUMIFS(E$3:E$9499,$G$3:$G$9499,$H7) -> 899490.79 | L7: =SUMIFS(F$3:F$9499,$G$3:$G$9499,$H7) -> 77991.804 | M7: =J7-K7-L7 -> 25549.9 | N7: =J7/$I7 -> 451.8821 | O7: =K7/$I7 -> 405.23491 | P7: =L7/$I7 -> 35.136549 | Q7: =N7-O7-P7 -> 11.510637
B8: =B7+1 -> 36531 | C8: 2149 | D8: 31096.64 | E8: 29230.841 | F8: 2798.6976 | G8: =YEAR(B8)&IF(MONTH(B8)<10,0&MONTH(B8),MONTH(B8)) -> 200001 | H8: 200006 | I8: =AVERAGEIFS(C$3:C$9499,$G$3:$G$9499,$H8) -> 2236.7 | J8: =SUMIFS(D$3:D$9499,$G$3:$G$9499,$H8) -> 979848.59 | K8: =SUMIFS(E$3:E$9499,$G$3:$G$9499,$H8) -> 871764.51 | L8: =SUMIFS(F$3:F$9499,$G$3:$G$9499,$H8) -> 72840.676 | M8: =J8-K8-L8 -> 35243.406 | N8: =J8/$I8 -> 438.07779 | O8: =K8/$I8 -> 389.75478 | P8: =L8/$I8 -> 32.566136 | Q8: =N8-O8-P8 -> 15.756877
B9: =B8+1 -> 36532 | C9: 2149 | D9: 31097.503 | E9: 28298.728 | F9: 1865.8502 | G9: =YEAR(B9)&IF(MONTH(B9)<10,0&MONTH(B9),MONTH(B9)) -> 200001 | H9: 200007 | I9: =AVERAGEIFS(C$3:C$9499,$G$3:$G$9499,$H9) -> 2252.4839 | J9: =SUMIFS(D$3:D$9499,$G$3:$G$9499,$H9) -> 1021488.9 | K9: =SUMIFS(E$3:E$9499,$G$3:$G$9499,$H9) -> 920978.64 | L9: =SUMIFS(F$3:F$9499,$G$3:$G$9499,$H9) -> 80072.514 | M9: =J9-K9-L9 -> 20437.765 | N9: =J9/$I9 -> 453.49444 | O9: =K9/$I9 -> 408.87247 | P9: =L9/$I9 -> 35.548541 | Q9: =N9-O9-P9 -> 9.0734346
B10: =B9+1 -> 36533 | C10: 2150 | D10: 31113.703 | E10: 28935.743 | F10: 1866.8222 | G10: =YEAR(B10)&IF(MONTH(B10)<10,0&MONTH(B10),MONTH(B10)) -> 200001 | H10: 200008 | I10: =AVERAGEIFS(C$3:C$9499,$G$3:$G$9499,$H10) -> 2271.5484 | J10: =SUMIFS(D$3:D$9499,$G$3:$G$9499,$H10) -> 1031865.8 | K10: =SUMIFS(E$3:E$9499,$G$3:$G$9499,$H10) -> 924358.23 | L10: =SUMIFS(F$3:F$9499,$G$3:$G$9499,$H10) -> 74897.302 | M10: =J10-K10-L10 -> 32610.254 | N10: =J10/$I10 -> 454.25657 | O10: =K10/$I10 -> 406.9287 | P10: =L10/$I10 -> 32.971916 | Q10: =N10-O10-P10 -> 14.355958
B11: =B10+1 -> 36534 | C11: 2150 | D11: 31114.567 | E11: 26758.527 | F11: 2178.0197 | G11: =YEAR(B11)&IF(MONTH(B11)<10,0&MONTH(B11),MONTH(B11)) -> 200001 | H11: 200009 | I11: =AVERAGEIFS(C$3:C$9499,$G$3:$G$9499,$H11) -> 2288.5333 | J11: =SUMIFS(D$3:D$9499,$G$3:$G$9499,$H11) -> 1007588.7 | K11: =SUMIFS(E$3:E$9499,$G$3:$G$9499,$H11) -> 910193.83 | L11: =SUMIFS(F$3:F$9499,$G$3:$G$9499,$H11) -> 72543.283 | M11: =J11-K11-L11 -> 24851.555 | N11: =J11/$I11 -> 440.27703 | O11: =K11/$I11 -> 397.71928 | P11: =L11/$I11 -> 31.698591 | Q11: =N11-O11-P11 -> 10.859163
B12: =B11+1 -> 36535 | C12: 2151 | D12: 31131.633 | E12: 26773.204 | F12: 2490.5306 | G12: =YEAR(B12)&IF(MONTH(B12)<10,0&MONTH(B12),MONTH(B12)) -> 200001 | H12: 200010 | I12: =AVERAGEIFS(C$3:C$9499,$G$3:$G$9499,$H12) -> 2306.4516 | J12: =SUMIFS(D$3:D$9499,$G$3:$G$9499,$H12) -> 1051128.2 | K12: =SUMIFS(E$3:E$9499,$G$3:$G$9499,$H12) -> 953790.3 | L12: =SUMIFS(F$3:F$9499,$G$3:$G$9499,$H12) -> 77314.547 | M12: =J12-K12-L12 -> 20023.402 | N12: =J12/$I12 -> 455.73393 | O12: =K12/$I12 -> 413.53146 | P12: =L12/$I12 -> 33.520993 | Q12: =N12-O12-P12 -> 8.6814751
B13: =B12+1 -> 36536 | C13: 2152 | D13: 31148.701 | E13: 28345.318 | F13: 2491.8961 | G13: =YEAR(B13)&IF(MONTH(B13)<10,0&MONTH(B13),MONTH(B13)) -> 200001 | H13: 200011 | I13: =AVERAGEIFS(C$3:C$9499,$G$3:$G$9499,$H13) -> 2327.4667 | J13: =SUMIFS(D$3:D$9499,$G$3:$G$9499,$H13) -> 1028216.4 | K13: =SUMIFS(E$3:E$9499,$G$3:$G$9499,$H13) -> 920585.71 | L13: =SUMIFS(F$3:F$9499,$G$3:$G$9499,$H13) -> 74710.187 | M13: =J13-K13-L13 -> 32920.509 | N13: =J13/$I13 -> 441.77492 | O13: =K13/$I13 -> 395.53121 | P13: =L13/$I13 -> 32.099359 | Q13: =N13-O13-P13 -> 14.144353
B14: =B13+1 -> 36537 | C14: 2152 | D14: 31151.297 | E14: 26790.116 | F14: 2492.1038 | G14: =YEAR(B14)&IF(MONTH(B14)<10,0&MONTH(B14),MONTH(B14)) -> 200001 | H14: 200012 | I14: =AVERAGEIFS(C$3:C$9499,$G$3:$G$9499,$H14) -> 2344.0968 | J14: =SUMIFS(D$3:D$9499,$G$3:$G$9499,$H14) -> 1071719.2 | K14: =SUMIFS(E$3:E$9499,$G$3:$G$9499,$H14) -> 969732.79 | L14: =SUMIFS(F$3:F$9499,$G$3:$G$9499,$H14) -> 79166.029 | M14: =J14-K14-L14 -> 22820.352 | N14: =J14/$I14 -> 457.1992 | O14: =K14/$I14 -> 413.69145 | P14: =L14/$I14 -> 33.772509 | Q14: =N14-O14-P14 -> 9.7352432
B15: =B14+1 -> 36538 | C15: 2153 | D15: 31166.638 | E15: 27426.642 | F15: 2181.6647 | G15: =YEAR(B15)&IF(MONTH(B15)<10,0&MONTH(B15),MONTH(B15)) -> 200001 | H15: 200101 | I15: =AVERAGEIFS(C$3:C$9499,$G$3:$G$9499,$H15) -> 2361.9032 | J15: =SUMIFS(D$3:D$9499,$G$3:$G$9499,$H15) -> 1081894.1 | K15: =SUMIFS(E$3:E$9499,$G$3:$G$9499,$H15) -> 964986.95 | L15: =SUMIFS(F$3:F$9499,$G$3:$G$9499,$H15) -> 84801.41 | M15: =J15-K15-L15 -> 32105.723 | N15: =J15/$I15 -> 458.06029 | O15: =K15/$I15 -> 408.56329 | P15: =L15/$I15 -> 35.903846 | Q15: =N15-O15-P15 -> 13.593158
... B314: =B313+1 -> 36837 | C314: 2322 | D314: 34177.012 | E314: 29050.46 | F314: 2050.6207 | G314: =YEAR(B314)&IF(MONTH(B314)<10,0&MONTH(B314),MONTH(B314)) -> 200011 | H314: 202512 | I314: =AVERAGEIFS(C$3:C$9499,$G$3:$G$9499,$H314) -> 35552.613 | J314: =SUMIFS(D$3:D$9499,$G$3:$G$9499,$H314) -> 27103598 | K314: =SUMIFS(E$3:E$9499,$G$3:$G$9499,$H314) -> 24375520 | L314: =SUMIFS(F$3:F$9499,$G$3:$G$9499,$H314) -> 1923725.3 | M314: =J314-K314-L314 -> 804353.07 | N314: =J314/$I314 -> 762.3518 | O314: =K314/$I314 -> 685.61824 | P314: =L314/$I314 -> 54.109253 | Q314: =N314-O314-P314 -> 22.624303
B315: =B314+1 -> 36838 | C315: 2323 | D315: 34194.58 | E315: 32484.851 | F315: 1709.729 | G315: =YEAR(B315)&IF(MONTH(B315)<10,0&MONTH(B315),MONTH(B315)) -> 200011
B316: =B315+1 -> 36839 | C316: 2324 | D316: 34212.151 | E316: 29764.571 | F316: 2736.9721 | G316: =YEAR(B316)&IF(MONTH(B316)<10,0&MONTH(B316),MONTH(B316)) -> 200011
B317: =B316+1 -> 36840 | C317: 2324 | D317: 34214.052 | E317: 30108.365 | F317: 3079.2646 | G317: =YEAR(B317)&IF(MONTH(B317)<10,0&MONTH(B317),MONTH(B317)) -> 200011
B318: =B317+1 -> 36841 | C318: 2325 | D318: 34229.724 | E318: 30464.455 | F318: 3080.6752 | G318: =YEAR(B318)&IF(MONTH(B318)<10,0&MONTH(B318),MONTH(B318)) -> 200011
B319: =B318+1 -> 36842 | C319: 2325 | D319: 34232.577 | E319: 29440.016 | F319: 1711.6288 | G319: =YEAR(B319)&IF(MONTH(B319)<10,0&MONTH(B319),MONTH(B319)) -> 200011
B320: =B319+1 -> 36843 | C320: 2326 | D320: 34249.203 | E320: 32536.743 | F320: 2054.9522 | G320: =YEAR(B320)&IF(MONTH(B320)<10,0&MONTH(B320),MONTH(B320)) -> 200011
B321: =B320+1 -> 36844 | C321: 2326 | D321: 34251.106 | E321: 30140.973 | F321: 2397.5774 | G321: =YEAR(B321)&IF(MONTH(B321)<10,0&MONTH(B321),MONTH(B321)) -> 200011
B322: =B321+1 -> 36845 | C322: 2327 | D322: 34268.687 | E322: 30499.131 | F322: 2056.1212 | G322: =YEAR(B322)&IF(MONTH(B322)<10,0&MONTH(B322),MONTH(B322)) -> 200011
B323: =B322+1 -> 36846 | C323: 2328 | D323: 34286.27 | E323: 31200.506 | F323: 2400.0389 | G323: =YEAR(B323)&IF(MONTH(B323)<10,0&MONTH(B323),MONTH(B323)) -> 200011
B324: =B323+1 -> 36847 | C324: 2329 | D324: 34301.951 | E324: 29499.678 | F324: 3430.1951 | G324: =YEAR(B324)&IF(MONTH(B324)<10,0&MONTH(B324),MONTH(B324)) -> 200011
B325: =B324+1 -> 36848 | C325: 2330 | D325: 34317.632 | E325: 29169.987 | F325: 3431.7632 | G325: =YEAR(B325)&IF(MONTH(B325)<10,0&MONTH(B325),MONTH(B325)) -> 200011
B326: =B325+1 -> 36849 | C326: 2330 | D326: 34318.586 | E326: 32602.656 | F326: 2402.301 | G326: =YEAR(B326)&IF(MONTH(B326)<10,0&MONTH(B326),MONTH(B326)) -> 200011
... B9499: =B9498+1 -> 46022 | C9499: 35712 | D9499: 878979.05 | E9499: 747132.19 | F9499: 43948.952 | G9499: =YEAR(B9499)&IF(MONTH(B9499)<10,0&MONTH(B9499),MONTH(B9499)) -> 202512

Sheet Task 3 - Lookup Tool
A1: SUMMARY | B1: AVERAGE | C1: TOTALS BY CATEGORY | G1: PER MEMBER | L1: LOOKUP TOOL
A2: YYYYMM | B2: Members | C2: Premiums | D2: Claims | E2: Expenses | F2: Profits | G2: Prem/Mem | H2: Claims/Mem | I2: Exp/Mem | J2: Profits/Mem | L2: YYYYMM | M2: Members | N2: Prem/Mem | O2: Claims/Mem | P2: Exp/Mem
A3: 200001 | B3: ='Task 2 - Analysis Table'!I3 -> 2154.0968 | C3: ='Task 2 - Analysis Table'!J3 -> 966792.45 | D3: ='Task 2 - Analysis Table'!K3 -> 863873.17 | E3: ='Task 2 - Analysis Table'!L3 -> 72985.325 | F3: ='Task 2 - Analysis Table'!M3 -> 29933.956 | G3: ='Task 2 - Analysis Table'!N3 -> 448.8157 | H3: ='Task 2 - Analysis Table'!O3 -> 401.03731 | I3: ='Task 2 - Analysis Table'!P3 -> 33.882101 | J3: ='Task 2 - Analysis Table'!Q3 -> 13.896291 | L3: 202501 | M3: =INDEX($B$3:$J$314,MATCH($L3,$A$3:$A$314,0),MATCH(M$2,$B$2:$J$2,0)) -> 32152.032 | N3: =INDEX($B$3:$J$314,MATCH($L3,$A$3:$A$314,0),MATCH(N$2,$B$2:$J$2,0)) -> 748.12643 | O3: =INDEX($B$3:$J$314,MATCH($L3,$A$3:$A$314,0),MATCH(O$2,$B$2:$J$2,0)) -> 668.48094 | P3: =INDEX($B$3:$J$314,MATCH($L3,$A$3:$A$314,0),MATCH(P$2,$B$2:$J$2,0)) -> 56.237857
A4: 200002 | B4: ='Task 2 - Analysis Table'!I4 -> 2171.4483 | C4: ='Task 2 - Analysis Table'!J4 -> 913328.62 | D4: ='Task 2 - Analysis Table'!K4 -> 814119.13 | E4: ='Task 2 - Analysis Table'!L4 -> 62677.37 | F4: ='Task 2 - Analysis Table'!M4 -> 36532.124 | G4: ='Task 2 - Analysis Table'!N4 -> 420.60805 | H4: ='Task 2 - Analysis Table'!O4 -> 374.91988 | I4: ='Task 2 - Analysis Table'!P4 -> 28.864316 | J4: ='Task 2 - Analysis Table'!Q4 -> 16.823852 | L4: 202502 | M4: =INDEX($B$3:$J$314,MATCH($L4,$A$3:$A$314,0),MATCH(M$2,$B$2:$J$2,0)) -> 32444.821 | N4: =INDEX($B$3:$J$314,MATCH($L4,$A$3:$A$314,0),MATCH(N$2,$B$2:$J$2,0)) -> 676.7742 | O4: =INDEX($B$3:$J$314,MATCH($L4,$A$3:$A$314,0),MATCH(O$2,$B$2:$J$2,0)) -> 609.79876 | P4: =INDEX($B$3:$J$314,MATCH($L4,$A$3:$A$314,0),MATCH(P$2,$B$2:$J$2,0)) -> 53.906348
A5: 200003 | B5: ='Task 2 - Analysis Table'!I5 -> 2187.7742 | C5: ='Task 2 - Analysis Table'!J5 -> 985298.95 | D5: ='Task 2 - Analysis Table'!K5 -> 881036.07 | E5: ='Task 2 - Analysis Table'!L5 -> 76594.593 | F5: ='Task 2 - Analysis Table'!M5 -> 27668.288 | G5: ='Task 2 - Analysis Table'!N5 -> 450.36592 | H5: ='Task 2 - Analysis Table'!O5 -> 402.70887 | I5: ='Task 2 - Analysis Table'!P5 -> 35.010283 | J5: ='Task 2 - Analysis Table'!Q5 -> 12.646775 | L5: 202503 | M5: =INDEX($B$3:$J$314,MATCH($L5,$A$3:$A$314,0),MATCH(M$2,$B$2:$J$2,0)) -> 32733.226 | N5: =INDEX($B$3:$J$314,MATCH($L5,$A$3:$A$314,0),MATCH(N$2,$B$2:$J$2,0)) -> 750.61625 | O5: =INDEX($B$3:$J$314,MATCH($L5,$A$3:$A$314,0),MATCH(O$2,$B$2:$J$2,0)) -> 674.35058 | P5: =INDEX($B$3:$J$314,MATCH($L5,$A$3:$A$314,0),MATCH(P$2,$B$2:$J$2,0)) -> 54.960084
A6: 200004 | B6: ='Task 2 - Analysis Table'!I6 -> 2202.5333 | C6: ='Task 2 - Analysis Table'!J6 -> 961495.21 | D6: ='Task 2 - Analysis Table'!K6 -> 868864.78 | E6: ='Task 2 - Analysis Table'!L6 -> 70190.545 | F6: ='Task 2 - Analysis Table'!M6 -> 22439.88 | G6: ='Task 2 - Analysis Table'!N6 -> 436.54059 | H6: ='Task 2 - Analysis Table'!O6 -> 394.48428 | I6: ='Task 2 - Analysis Table'!P6 -> 31.868097 | J6: ='Task 2 - Analysis Table'!Q6 -> 10.188214 | L6: 202504 | M6: =INDEX($B$3:$J$314,MATCH($L6,$A$3:$A$314,0),MATCH(M$2,$B$2:$J$2,0)) -> 33052.833 | N6: =INDEX($B$3:$J$314,MATCH($L6,$A$3:$A$314,0),MATCH(N$2,$B$2:$J$2,0)) -> 727.65596 | O6: =INDEX($B$3:$J$314,MATCH($L6,$A$3:$A$314,0),MATCH(O$2,$B$2:$J$2,0)) -> 655.36587 | P6: =INDEX($B$3:$J$314,MATCH($L6,$A$3:$A$314,0),MATCH(P$2,$B$2:$J$2,0)) -> 50.210799
A7: 200005 | B7: ='Task 2 - Analysis Table'!I7 -> 2219.6774 | C7: ='Task 2 - Analysis Table'!J7 -> 1003032.5 | D7: ='Task 2 - Analysis Table'!K7 -> 899490.79 | E7: ='Task 2 - Analysis Table'!L7 -> 77991.804 | F7: ='Task 2 - Analysis Table'!M7 -> 25549.9 | G7: ='Task 2 - Analysis Table'!N7 -> 451.8821 | H7: ='Task 2 - Analysis Table'!O7 -> 405.23491 | I7: ='Task 2 - Analysis Table'!P7 -> 35.136549 | J7: ='Task 2 - Analysis Table'!Q7 -> 11.510637 | L7: 202505 | M7: =INDEX($B$3:$J$314,MATCH($L7,$A$3:$A$314,0),MATCH(M$2,$B$2:$J$2,0)) -> 33388.355 | N7: =INDEX($B$3:$J$314,MATCH($L7,$A$3:$A$314,0),MATCH(N$2,$B$2:$J$2,0)) -> 753.22084 | O7: =INDEX($B$3:$J$314,MATCH($L7,$A$3:$A$314,0),MATCH(O$2,$B$2:$J$2,0)) -> 678.6155 | P7: =INDEX($B$3:$J$314,MATCH($L7,$A$3:$A$314,0),MATCH(P$2,$B$2:$J$2,0)) -> 57.348882
A8: 200006 | B8: ='Task 2 - Analysis Table'!I8 -> 2236.7 | C8: ='Task 2 - Analysis Table'!J8 -> 979848.59 | D8: ='Task 2 - Analysis Table'!K8 -> 871764.51 | E8: ='Task 2 - Analysis Table'!L8 -> 72840.676 | F8: ='Task 2 - Analysis Table'!M8 -> 35243.406 | G8: ='Task 2 - Analysis Table'!N8 -> 438.07779 | H8: ='Task 2 - Analysis Table'!O8 -> 389.75478 | I8: ='Task 2 - Analysis Table'!P8 -> 32.566136 | J8: ='Task 2 - Analysis Table'!Q8 -> 15.756877 | L8: 202506 | M8: =INDEX($B$3:$J$314,MATCH($L8,$A$3:$A$314,0),MATCH(M$2,$B$2:$J$2,0)) -> 33714.6 | N8: =INDEX($B$3:$J$314,MATCH($L8,$A$3:$A$314,0),MATCH(N$2,$B$2:$J$2,0)) -> 730.27891 | O8: =INDEX($B$3:$J$314,MATCH($L8,$A$3:$A$314,0),MATCH(O$2,$B$2:$J$2,0)) -> 660.92197 | P8: =INDEX($B$3:$J$314,MATCH($L8,$A$3:$A$314,0),MATCH(P$2,$B$2:$J$2,0)) -> 54.292995
A9: 200007 | B9: ='Task 2 - Analysis Table'!I9 -> 2252.4839 | C9: ='Task 2 - Analysis Table'!J9 -> 1021488.9 | D9: ='Task 2 - Analysis Table'!K9 -> 920978.64 | E9: ='Task 2 - Analysis Table'!L9 -> 80072.514 | F9: ='Task 2 - Analysis Table'!M9 -> 20437.765 | G9: ='Task 2 - Analysis Table'!N9 -> 453.49444 | H9: ='Task 2 - Analysis Table'!O9 -> 408.87247 | I9: ='Task 2 - Analysis Table'!P9 -> 35.548541 | J9: ='Task 2 - Analysis Table'!Q9 -> 9.0734346 | L9: 202507 | M9: =INDEX($B$3:$J$314,MATCH($L9,$A$3:$A$314,0),MATCH(M$2,$B$2:$J$2,0)) -> 34034.194 | N9: =INDEX($B$3:$J$314,MATCH($L9,$A$3:$A$314,0),MATCH(N$2,$B$2:$J$2,0)) -> 755.93665 | O9: =INDEX($B$3:$J$314,MATCH($L9,$A$3:$A$314,0),MATCH(O$2,$B$2:$J$2,0)) -> 678.65237 | P9: =INDEX($B$3:$J$314,MATCH($L9,$A$3:$A$314,0),MATCH(P$2,$B$2:$J$2,0)) -> 60.716496
A10: 200008 | B10: ='Task 2 - Analysis Table'!I10 -> 2271.5484 | C10: ='Task 2 - Analysis Table'!J10 -> 1031865.8 | D10: ='Task 2 - Analysis Table'!K10 -> 924358.23 | E10: ='Task 2 - Analysis Table'!L10 -> 74897.302 | F10: ='Task 2 - Analysis Table'!M10 -> 32610.254 | G10: ='Task 2 - Analysis Table'!N10 -> 454.25657 | H10: ='Task 2 - Analysis Table'!O10 -> 406.9287 | I10: ='Task 2 - Analysis Table'!P10 -> 32.971916 | J10: ='Task 2 - Analysis Table'!Q10 -> 14.355958 | L10: 202508 | M10: =INDEX($B$3:$J$314,MATCH($L10,$A$3:$A$314,0),MATCH(M$2,$B$2:$J$2,0)) -> 34349.484 | N10: =INDEX($B$3:$J$314,MATCH($L10,$A$3:$A$314,0),MATCH(N$2,$B$2:$J$2,0)) -> 757.2498 | O10: =INDEX($B$3:$J$314,MATCH($L10,$A$3:$A$314,0),MATCH(O$2,$B$2:$J$2,0)) -> 685.17992 | P10: =INDEX($B$3:$J$314,MATCH($L10,$A$3:$A$314,0),MATCH(P$2,$B$2:$J$2,0)) -> 55.20706
A11: 200009 | B11: ='Task 2 - Analysis Table'!I11 -> 2288.5333 | C11: ='Task 2 - Analysis Table'!J11 -> 1007588.7 | D11: ='Task 2 - Analysis Table'!K11 -> 910193.83 | E11: ='Task 2 - Analysis Table'!L11 -> 72543.283 | F11: ='Task 2 - Analysis Table'!M11 -> 24851.555 | G11: ='Task 2 - Analysis Table'!N11 -> 440.27703 | H11: ='Task 2 - Analysis Table'!O11 -> 397.71928 | I11: ='Task 2 - Analysis Table'!P11 -> 31.698591 | J11: ='Task 2 - Analysis Table'!Q11 -> 10.859163 | L11: 202509 | M11: =INDEX($B$3:$J$314,MATCH($L11,$A$3:$A$314,0),MATCH(M$2,$B$2:$J$2,0)) -> 34632.2 | N11: =INDEX($B$3:$J$314,MATCH($L11,$A$3:$A$314,0),MATCH(N$2,$B$2:$J$2,0)) -> 734.04571 | O11: =INDEX($B$3:$J$314,MATCH($L11,$A$3:$A$314,0),MATCH(O$2,$B$2:$J$2,0)) -> 655.73861 | P11: =INDEX($B$3:$J$314,MATCH($L11,$A$3:$A$314,0),MATCH(P$2,$B$2:$J$2,0)) -> 53.100758
A12: 200010 | B12: ='Task 2 - Analysis Table'!I12 -> 2306.4516 | C12: ='Task 2 - Analysis Table'!J12 -> 1051128.2 | D12: ='Task 2 - Analysis Table'!K12 -> 953790.3 | E12: ='Task 2 - Analysis Table'!L12 -> 77314.547 | F12: ='Task 2 - Analysis Table'!M12 -> 20023.402 | G12: ='Task 2 - Analysis Table'!N12 -> 455.73393 | H12: ='Task 2 - Analysis Table'!O12 -> 413.53146 | I12: ='Task 2 - Analysis Table'!P12 -> 33.520993 | J12: ='Task 2 - Analysis Table'!Q12 -> 8.6814751 | L12: 202510 | M12: =INDEX($B$3:$J$314,MATCH($L12,$A$3:$A$314,0),MATCH(M$2,$B$2:$J$2,0)) -> 34907.419 | N12: =INDEX($B$3:$J$314,MATCH($L12,$A$3:$A$314,0),MATCH(N$2,$B$2:$J$2,0)) -> 759.84548 | O12: =INDEX($B$3:$J$314,MATCH($L12,$A$3:$A$314,0),MATCH(O$2,$B$2:$J$2,0)) -> 681.63368 | P12: =INDEX($B$3:$J$314,MATCH($L12,$A$3:$A$314,0),MATCH(P$2,$B$2:$J$2,0)) -> 58.822132
A13: 200011 | B13: ='Task 2 - Analysis Table'!I13 -> 2327.4667 | C13: ='Task 2 - Analysis Table'!J13 -> 1028216.4 | D13: ='Task 2 - Analysis Table'!K13 -> 920585.71 | E13: ='Task 2 - Analysis Table'!L13 -> 74710.187 | F13: ='Task 2 - Analysis Table'!M13 -> 32920.509 | G13: ='Task 2 - Analysis Table'!N13 -> 441.77492 | H13: ='Task 2 - Analysis Table'!O13 -> 395.53121 | I13: ='Task 2 - Analysis Table'!P13 -> 32.099359 | J13: ='Task 2 - Analysis Table'!Q13 -> 14.144353 | L13: 202511 | M13: =INDEX($B$3:$J$314,MATCH($L13,$A$3:$A$314,0),MATCH(M$2,$B$2:$J$2,0)) -> 35216.433 | N13: =INDEX($B$3:$J$314,MATCH($L13,$A$3:$A$314,0),MATCH(N$2,$B$2:$J$2,0)) -> 736.57294 | O13: =INDEX($B$3:$J$314,MATCH($L13,$A$3:$A$314,0),MATCH(O$2,$B$2:$J$2,0)) -> 670.05348 | P13: =INDEX($B$3:$J$314,MATCH($L13,$A$3:$A$314,0),MATCH(P$2,$B$2:$J$2,0)) -> 55.978167
A14: 200012 | B14: ='Task 2 - Analysis Table'!I14 -> 2344.0968 | C14: ='Task 2 - Analysis Table'!J14 -> 1071719.2 | D14: ='Task 2 - Analysis Table'!K14 -> 969732.79 | E14: ='Task 2 - Analysis Table'!L14 -> 79166.029 | F14: ='Task 2 - Analysis Table'!M14 -> 22820.352 | G14: ='Task 2 - Analysis Table'!N14 -> 457.1992 | H14: ='Task 2 - Analysis Table'!O14 -> 413.69145 | I14: ='Task 2 - Analysis Table'!P14 -> 33.772509 | J14: ='Task 2 - Analysis Table'!Q14 -> 9.7352432 | L14: 202512 | M14: =INDEX($B$3:$J$314,MATCH($L14,$A$3:$A$314,0),MATCH(M$2,$B$2:$J$2,0)) -> 35552.613 | N14: =INDEX($B$3:$J$314,MATCH($L14,$A$3:$A$314,0),MATCH(N$2,$B$2:$J$2,0)) -> 762.3518 | O14: =INDEX($B$3:$J$314,MATCH($L14,$A$3:$A$314,0),MATCH(O$2,$B$2:$J$2,0)) -> 685.61824 | P14: =INDEX($B$3:$J$314,MATCH($L14,$A$3:$A$314,0),MATCH(P$2,$B$2:$J$2,0)) -> 54.109253
A15: 200101 | B15: ='Task 2 - Analysis Table'!I15 -> 2361.9032 | C15: ='Task 2 - Analysis Table'!J15 -> 1081894.1 | D15: ='Task 2 - Analysis Table'!K15 -> 964986.95 | E15: ='Task 2 - Analysis Table'!L15 -> 84801.41 | F15: ='Task 2 - Analysis Table'!M15 -> 32105.723 | G15: ='Task 2 - Analysis Table'!N15 -> 458.06029 | H15: ='Task 2 - Analysis Table'!O15 -> 408.56329 | I15: ='Task 2 - Analysis Table'!P15 -> 35.903846 | J15: ='Task 2 - Analysis Table'!Q15 -> 13.593158
A16: 200102 | B16: ='Task 2 - Analysis Table'!I16 -> 2379.1071 | C16: ='Task 2 - Analysis Table'!J16 -> 986042.88 | D16: ='Task 2 - Analysis Table'!K16 -> 894814.57 | E16: ='Task 2 - Analysis Table'!L16 -> 73971.591 | F16: ='Task 2 - Analysis Table'!M16 -> 17256.72 | G16: ='Task 2 - Analysis Table'!N16 -> 414.45922 | H16: ='Task 2 - Analysis Table'!O16 -> 376.11361 | I16: ='Task 2 - Analysis Table'!P16 -> 31.092165 | J16: ='Task 2 - Analysis Table'!Q16 -> 7.2534436
A17: 200103 | B17: ='Task 2 - Analysis Table'!I17 -> 2396.9677 | C17: ='Task 2 - Analysis Table'!J17 -> 1101633.1 | D17: ='Task 2 - Analysis Table'!K17 -> 996465.83 | E17: ='Task 2 - Analysis Table'!L17 -> 84580.912 | F17: ='Task 2 - Analysis Table'!M17 -> 20586.354 | G17: ='Task 2 - Analysis Table'!N17 -> 459.59446 | H17: ='Task 2 - Analysis Table'!O17 -> 415.71933 | I17: ='Task 2 - Analysis Table'!P17 -> 35.286629 | J17: ='Task 2 - Analysis Table'!Q17 -> 8.5884988
A18: 200104 | B18: ='Task 2 - Analysis Table'!I18 -> 2416.6 | C18: ='Task 2 - Analysis Table'!J18 -> 1076555.8 | D18: ='Task 2 - Analysis Table'!K18 -> 962106.05 | E18: ='Task 2 - Analysis Table'!L18 -> 88284.888 | F18: ='Task 2 - Analysis Table'!M18 -> 26164.904 | G18: ='Task 2 - Analysis Table'!N18 -> 445.48367 | H18: ='Task 2 - Analysis Table'!O18 -> 398.12383 | I18: ='Task 2 - Analysis Table'!P18 -> 36.532686 | J18: ='Task 2 - Analysis Table'!Q18 -> 10.827155
A19: 200105 | B19: ='Task 2 - Analysis Table'!I19 -> 2435.4516 | C19: ='Task 2 - Analysis Table'!J19 -> 1122838.8 | D19: ='Task 2 - Analysis Table'!K19 -> 1001868.5 | E19: ='Task 2 - Analysis Table'!L19 -> 83678.498 | F19: ='Task 2 - Analysis Table'!M19 -> 37291.781 | G19: ='Task 2 - Analysis Table'!N19 -> 461.03926 | H19: ='Task 2 - Analysis Table'!O19 -> 411.36869 | I19: ='Task 2 - Analysis Table'!P19 -> 34.358514 | J19: ='Task 2 - Analysis Table'!Q19 -> 15.31206
A20: 200106 | B20: ='Task 2 - Analysis Table'!I20 -> 2453.3 | C20: ='Task 2 - Analysis Table'!J20 -> 1096421.2 | D20: ='Task 2 - Analysis Table'!K20 -> 993718.13 | E20: ='Task 2 - Analysis Table'!L20 -> 84419.542 | F20: ='Task 2 - Analysis Table'!M20 -> 18283.565 | G20: ='Task 2 - Analysis Table'!N20 -> 446.9169 | H20: ='Task 2 - Analysis Table'!O20 -> 405.05365 | I20: ='Task 2 - Analysis Table'!P20 -> 34.410607 | J20: ='Task 2 - Analysis Table'!Q20 -> 7.4526415
A21: 200107 | B21: ='Task 2 - Analysis Table'!I21 -> 2472.0323 | C21: ='Task 2 - Analysis Table'!J21 -> 1143612.2 | D21: ='Task 2 - Analysis Table'!K21 -> 1021829.6 | E21: ='Task 2 - Analysis Table'!L21 -> 91486.414 | F21: ='Task 2 - Analysis Table'!M21 -> 30296.127 | G21: ='Task 2 - Analysis Table'!N21 -> 462.62025 | H21: ='Task 2 - Analysis Table'!O21 -> 413.35611 | I21: ='Task 2 - Analysis Table'!P21 -> 37.008584 | J21: ='Task 2 - Analysis Table'!Q21 -> 12.255555
A22: 200108 | B22: ='Task 2 - Analysis Table'!I22 -> 2495.3548 | C22: ='Task 2 - Analysis Table'!J22 -> 1156417.4 | D22: ='Task 2 - Analysis Table'!K22 -> 1033290.5 | E22: ='Task 2 - Analysis Table'!L22 -> 91005.478 | F22: ='Task 2 - Analysis Table'!M22 -> 32121.479 | G22: ='Task 2 - Analysis Table'!N22 -> 463.42805 | H22: ='Task 2 - Analysis Table'!O22 -> 414.08558 | I22: ='Task 2 - Analysis Table'!P22 -> 36.469955 | J22: ='Task 2 - Analysis Table'!Q22 -> 12.87251
A23: 200109 | B23: ='Task 2 - Analysis Table'!I23 -> 2521.2333 | C23: ='Task 2 - Analysis Table'!J23 -> 1132569.3 | D23: ='Task 2 - Analysis Table'!K23 -> 1025701 | E23: ='Task 2 - Analysis Table'!L23 -> 80396.818 | F23: ='Task 2 - Analysis Table'!M23 -> 26471.505 | G23: ='Task 2 - Analysis Table'!N23 -> 449.21241 | H23: ='Task 2 - Analysis Table'!O23 -> 406.82509 | I23: ='Task 2 - Analysis Table'!P23 -> 31.887893 | J23: ='Task 2 - Analysis Table'!Q23 -> 10.499427
A24: 200110 | B24: ='Task 2 - Analysis Table'!I24 -> 2544.9677 | C24: ='Task 2 - Analysis Table'!J24 -> 1183158.3 | D24: ='Task 2 - Analysis Table'!K24 -> 1068266.8 | E24: ='Task 2 - Analysis Table'!L24 -> 87786.091 | F24: ='Task 2 - Analysis Table'!M24 -> 27105.36 | G24: ='Task 2 - Analysis Table'!N24 -> 464.90109 | H24: ='Task 2 - Analysis Table'!O24 -> 419.75653 | I24: ='Task 2 - Analysis Table'!P24 -> 34.49399 | J24: ='Task 2 - Analysis Table'!Q24 -> 10.650571
A25: 200111 | B25: ='Task 2 - Analysis Table'!I25 -> 2570.7333 | C25: ='Task 2 - Analysis Table'!J25 -> 1158352.1 | D25: ='Task 2 - Analysis Table'!K25 -> 1064138.8 | E25: ='Task 2 - Analysis Table'!L25 -> 81490.865 | F25: ='Task 2 - Analysis Table'!M25 -> 12722.497 | G25: ='Task 2 - Analysis Table'!N25 -> 450.5921 | H25: ='Task 2 - Analysis Table'!O25 -> 413.94367 | I25: ='Task 2 - Analysis Table'!P25 -> 31.699463 | J25: ='Task 2 - Analysis Table'!Q25 -> 4.9489758
A26: 200112 | B26: ='Task 2 - Analysis Table'!I26 -> 2593.2903 | C26: ='Task 2 - Analysis Table'!J26 -> 1209582.9 | D26: ='Task 2 - Analysis Table'!K26 -> 1093686.5 | E26: ='Task 2 - Analysis Table'!L26 -> 89345.823 | F26: ='Task 2 - Analysis Table'!M26 -> 26550.632 | G26: ='Task 2 - Analysis Table'!N26 -> 466.4279 | H26: ='Task 2 - Analysis Table'!O26 -> 421.737 | I26: ='Task 2 - Analysis Table'!P26 -> 34.452688 | J26: ='Task 2 - Analysis Table'!Q26 -> 10.238203
... A314: 202512 | B314: ='Task 2 - Analysis Table'!I314 -> 35552.613 | C314: ='Task 2 - Analysis Table'!J314 -> 27103598 | D314: ='Task 2 - Analysis Table'!K314 -> 24375520 | E314: ='Task 2 - Analysis Table'!L314 -> 1923725.3 | F314: ='Task 2 - Analysis Table'!M314 -> 804353.07 | G314: ='Task 2 - Analysis Table'!N314 -> 762.3518 | H314: ='Task 2 - Analysis Table'!O314 -> 685.61824 | I314: ='Task 2 - Analysis Table'!P314 -> 54.109253 | J314: ='Task 2 - Analysis Table'!Q314 -> 22.624303

Sheet Task 4 - Forecasting
A1: LOOKUP TOOL: PER MEMBER RESULTS | F1: APPLY TREND? | J1: FACTORS | N1: PROJECTION RESULTS: PER MEMBER BASIS
A2: YYYYMM | B2: Members | C2: Prem/Mem | D2: Claims/Mem | E2: Exp/Mem | F2: Mem. | G2: Prem. | H2: Claims | I2: Exp. | J2: Mem. | K2: Prem. | L2: Claims | M2: Exp. | N2: YYYYMM | O2: Members | P2: Premiums | Q2: Claims | R2: Expenses | S2: Profits
A3: 202501 | B3: ='Task 3 - Lookup Tool'!M3 -> 32152.032 | C3: ='Task 3 - Lookup Tool'!N3 -> 748.12643 | D3: ='Task 3 - Lookup Tool'!O3 -> 668.48094 | E3: ='Task 3 - Lookup Tool'!P3 -> 56.237857 | F3: Y | G3: Y | H3: N | I3: Y | J3: =IF(F3="Y",'Trend Factors Table'!B3,1) -> 1.01 | K3: =IF(G3="Y",'Trend Factors Table'!C3,1) -> 1.03 | L3: =IF(H3="Y",'Trend Factors Table'!D3,1) -> 1 | M3: =IF(I3="Y",'Trend Factors Table'!E3,1) -> 1.03 | N3: 202601 | O3: =B3*J3 -> 32473.553 | P3: =C3*K3 -> 770.57023 | Q3: =D3*L3 -> 668.48094 | R3: =E3*M3 -> 57.924993 | S3: =P3-Q3-R3 -> 44.1643
A4: 202502 | B4: ='Task 3 - Lookup Tool'!M4 -> 32444.821 | C4: ='Task 3 - Lookup Tool'!N4 -> 676.7742 | D4: ='Task 3 - Lookup Tool'!O4 -> 609.79876 | E4: ='Task 3 - Lookup Tool'!P4 -> 53.906348 | F4: Y | G4: Y | H4: Y | I4: N | J4: =IF(F4="Y",'Trend Factors Table'!B4,1) -> 1.01 | K4: =IF(G4="Y",'Trend Factors Table'!C4,1) -> 1.03 | L4: =IF(H4="Y",'Trend Factors Table'!D4,1) -> 1.03 | M4: =IF(I4="Y",'Trend Factors Table'!E4,1) -> 1 | N4: 202602 | O4: =B4*J4 -> 32769.27 | P4: =C4*K4 -> 697.07742 | Q4: =D4*L4 -> 628.09273 | R4: =E4*M4 -> 53.906348 | S4: =P4-Q4-R4 -> 15.078348
A5: 202503 | B5: ='Task 3 - Lookup Tool'!M5 -> 32733.226 | C5: ='Task 3 - Lookup Tool'!N5 -> 750.61625 | D5: ='Task 3 - Lookup Tool'!O5 -> 674.35058 | E5: ='Task 3 - Lookup Tool'!P5 -> 54.960084 | F5: Y | G5: N | H5: Y | I5: Y | J5: =IF(F5="Y",'Trend Factors Table'!B5,1) -> 1.01 | K5: =IF(G5="Y",'Trend Factors Table'!C5,1) -> 1 | L5: =IF(H5="Y",'Trend Factors Table'!D5,1) -> 1.03 | M5: =IF(I5="Y",'Trend Factors Table'!E5,1) -> 1.01 | N5: 202603 | O5: =B5*J5 -> 33060.558 | P5: =C5*K5 -> 750.61625 | Q5: =D5*L5 -> 694.5811 | R5: =E5*M5 -> 55.509685 | S5: =P5-Q5-R5 -> 0.52546713
A6: 202504 | B6: ='Task 3 - Lookup Tool'!M6 -> 33052.833 | C6: ='Task 3 - Lookup Tool'!N6 -> 727.65596 | D6: ='Task 3 - Lookup Tool'!O6 -> 655.36587 | E6: ='Task 3 - Lookup Tool'!P6 -> 50.210799 | F6: Y | G6: Y | H6: N | I6: Y | J6: =IF(F6="Y",'Trend Factors Table'!B6,1) -> 1.01 | K6: =IF(G6="Y",'Trend Factors Table'!C6,1) -> 1.05 | L6: =IF(H6="Y",'Trend Factors Table'!D6,1) -> 1 | M6: =IF(I6="Y",'Trend Factors Table'!E6,1) -> 1.03 | N6: 202604 | O6: =B6*J6 -> 33383.362 | P6: =C6*K6 -> 764.03876 | Q6: =D6*L6 -> 655.36587 | R6: =E6*M6 -> 51.717123 | S6: =P6-Q6-R6 -> 56.955763
A7: 202505 | B7: ='Task 3 - Lookup Tool'!M7 -> 33388.355 | C7: ='Task 3 - Lookup Tool'!N7 -> 753.22084 | D7: ='Task 3 - Lookup Tool'!O7 -> 678.6155 | E7: ='Task 3 - Lookup Tool'!P7 -> 57.348882 | F7: Y | G7: Y | H7: Y | I7: N | J7: =IF(F7="Y",'Trend Factors Table'!B7,1) -> 1.01 | K7: =IF(G7="Y",'Trend Factors Table'!C7,1) -> 1.05 | L7: =IF(H7="Y",'Trend Factors Table'!D7,1) -> 1.03 | M7: =IF(I7="Y",'Trend Factors Table'!E7,1) -> 1 | N7: 202605 | O7: =B7*J7 -> 33722.238 | P7: =C7*K7 -> 790.88188 | Q7: =D7*L7 -> 698.97396 | R7: =E7*M7 -> 57.348882 | S7: =P7-Q7-R7 -> 34.559039
A8: 202506 | B8: ='Task 3 - Lookup Tool'!M8 -> 33714.6 | C8: ='Task 3 - Lookup Tool'!N8 -> 730.27891 | D8: ='Task 3 - Lookup Tool'!O8 -> 660.92197 | E8: ='Task 3 - Lookup Tool'!P8 -> 54.292995 | F8: Y | G8: N | H8: Y | I8: Y | J8: =IF(F8="Y",'Trend Factors Table'!B8,1) -> 1.01 | K8: =IF(G8="Y",'Trend Factors Table'!C8,1) -> 1 | L8: =IF(H8="Y",'Trend Factors Table'!D8,1) -> 1.03 | M8: =IF(I8="Y",'Trend Factors Table'!E8,1) -> 1.02 | N8: 202606 | O8: =B8*J8 -> 34051.746 | P8: =C8*K8 -> 730.27891 | Q8: =D8*L8 -> 680.74963 | R8: =E8*M8 -> 55.378855 | S8: =P8-Q8-R8 -> -5.8495814
A9: 202507 | B9: ='Task 3 - Lookup Tool'!M9 -> 34034.194 | C9: ='Task 3 - Lookup Tool'!N9 -> 755.93665 | D9: ='Task 3 - Lookup Tool'!O9 -> 678.65237 | E9: ='Task 3 - Lookup Tool'!P9 -> 60.716496 | F9: Y | G9: Y | H9: N | I9: Y | J9: =IF(F9="Y",'Trend Factors Table'!B9,1) -> 1.01 | K9: =IF(G9="Y",'Trend Factors Table'!C9,1) -> 1.05 | L9: =IF(H9="Y",'Trend Factors Table'!D9,1) -> 1 | M9: =IF(I9="Y",'Trend Factors Table'!E9,1) -> 1.03 | N9: 202607 | O9: =B9*J9 -> 34374.535 | P9: =C9*K9 -> 793.73348 | Q9: =D9*L9 -> 678.65237 | R9: =E9*M9 -> 62.537991 | S9: =P9-Q9-R9 -> 52.543127
A10: 202508 | B10: ='Task 3 - Lookup Tool'!M10 -> 34349.484 | C10: ='Task 3 - Lookup Tool'!N10 -> 757.2498 | D10: ='Task 3 - Lookup Tool'!O10 -> 685.17992 | E10: ='Task 3 - Lookup Tool'!P10 -> 55.20706 | F10: Y | G10: Y | H10: Y | I10: N | J10: =IF(F10="Y",'Trend Factors Table'!B10,1) -> 1.01 | K10: =IF(G10="Y",'Trend Factors Table'!C10,1) -> 1.04 | L10: =IF(H10="Y",'Trend Factors Table'!D10,1) -> 1.03 | M10: =IF(I10="Y",'Trend Factors Table'!E10,1) -> 1 | N10: 202608 | O10: =B10*J10 -> 34692.979 | P10: =C10*K10 -> 787.53979 | Q10: =D10*L10 -> 705.73531 | R10: =E10*M10 -> 55.20706 | S10: =P10-Q10-R10 -> 26.59742
A11: 202509 | B11: ='Task 3 - Lookup Tool'!M11 -> 34632.2 | C11: ='Task 3 - Lookup Tool'!N11 -> 734.04571 | D11: ='Task 3 - Lookup Tool'!O11 -> 655.73861 | E11: ='Task 3 - Lookup Tool'!P11 -> 53.100758 | F11: Y | G11: N | H11: Y | I11: Y | J11: =IF(F11="Y",'Trend Factors Table'!B11,1) -> 1.01 | K11: =IF(G11="Y",'Trend Factors Table'!C11,1) -> 1 | L11: =IF(H11="Y",'Trend Factors Table'!D11,1) -> 1.03 | M11: =IF(I11="Y",'Trend Factors Table'!E11,1) -> 1.03 | N11: 202609 | O11: =B11*J11 -> 34978.522 | P11: =C11*K11 -> 734.04571 | Q11: =D11*L11 -> 675.41077 | R11: =E11*M11 -> 54.69378 | S11: =P11-Q11-R11 -> 3.9411644
A12: 202510 | B12: ='Task 3 - Lookup Tool'!M12 -> 34907.419 | C12: ='Task 3 - Lookup Tool'!N12 -> 759.84548 | D12: ='Task 3 - Lookup Tool'!O12 -> 681.63368 | E12: ='Task 3 - Lookup Tool'!P12 -> 58.822132 | F12: Y | G12: Y | H12: N | I12: Y | J12: =IF(F12="Y",'Trend Factors Table'!B12,1) -> 1.01 | K12: =IF(G12="Y",'Trend Factors Table'!C12,1) -> 1.03 | L12: =IF(H12="Y",'Trend Factors Table'!D12,1) -> 1 | M12: =IF(I12="Y",'Trend Factors Table'!E12,1) -> 1.01 | N12: 202610 | O12: =B12*J12 -> 35256.494 | P12: =C12*K12 -> 782.64084 | Q12: =D12*L12 -> 681.63368 | R12: =E12*M12 -> 59.410354 | S12: =P12-Q12-R12 -> 41.596808
A13: 202511 | B13: ='Task 3 - Lookup Tool'!M13 -> 35216.433 | C13: ='Task 3 - Lookup Tool'!N13 -> 736.57294 | D13: ='Task 3 - Lookup Tool'!O13 -> 670.05348 | E13: ='Task 3 - Lookup Tool'!P13 -> 55.978167 | F13: Y | G13: Y | H13: Y | I13: N | J13: =IF(F13="Y",'Trend Factors Table'!B13,1) -> 1.01 | K13: =IF(G13="Y",'Trend Factors Table'!C13,1) -> 1.04 | L13: =IF(H13="Y",'Trend Factors Table'!D13,1) -> 1.03 | M13: =IF(I13="Y",'Trend Factors Table'!E13,1) -> 1 | N13: 202611 | O13: =B13*J13 -> 35568.598 | P13: =C13*K13 -> 766.03586 | Q13: =D13*L13 -> 690.15508 | R13: =E13*M13 -> 55.978167 | S13: =P13-Q13-R13 -> 19.902612
A14: 202512 | B14: ='Task 3 - Lookup Tool'!M14 -> 35552.613 | C14: ='Task 3 - Lookup Tool'!N14 -> 762.3518 | D14: ='Task 3 - Lookup Tool'!O14 -> 685.61824 | E14: ='Task 3 - Lookup Tool'!P14 -> 54.109253 | F14: Y | G14: N | H14: Y | I14: Y | J14: =IF(F14="Y",'Trend Factors Table'!B14,1) -> 1.01 | K14: =IF(G14="Y",'Trend Factors Table'!C14,1) -> 1 | L14: =IF(H14="Y",'Trend Factors Table'!D14,1) -> 1.02 | M14: =IF(I14="Y",'Trend Factors Table'!E14,1) -> 1.02 | N14: 202612 | O14: =B14*J14 -> 35908.139 | P14: =C14*K14 -> 762.3518 | Q14: =D14*L14 -> 699.3306 | R14: =E14*M14 -> 55.191438 | S14: =P14-Q14-R14 -> 7.8297527
N15: Totals | P15: =SUMPRODUCT($O$3:$O$14,P3:P14) -> 3.1222221e+08 | Q15: =SUMPRODUCT($O$3:$O$14,Q3:Q14) -> 2.7901214e+08 | R15: =SUMPRODUCT($O$3:$O$14,R3:R14) -> 23074461 | S15: =SUMPRODUCT($O$3:$O$14,S3:S14) -> 10135608

Sheet Task 5 - Projected vs. Actual
B1: PROJECTION RESULTS: AGGREGATE BASIS | G1: ACTUAL RESULTS: AGGREGATE BASIS | L1: % DIFFERENTIAL: PROJECTED VS. ACTUAL
A2: YYYYMM | B2: Members | C2: Premiums | D2: Claims | E2: Expenses | F2: Profits | G2: Members | H2: Premiums | I2: Claims | J2: Expenses | K2: Profits | L2: Members | M2: Premiums | N2: Claims | O2: Expenses
A3: 202601 | B3: ='Task 4 - Forecasting'!O3 -> 32473.553 | C3: ='Task 4 - Forecasting'!$O3*'Task 4 - Forecasting'!P3 -> 25023153 | D3: ='Task 4 - Forecasting'!$O3*'Task 4 - Forecasting'!Q3 -> 21707951 | E3: ='Task 4 - Forecasting'!$O3*'Task 4 - Forecasting'!R3 -> 1881030.3 | F3: =C3-D3-E3 -> 1434171.7 | G3: {=INDIRECT($A3&"!"&"C13")} -> 31178.239 | H3: {=INDIRECT($A3&"!"&"D13")} -> 25953471 | I3: {=INDIRECT($A3&"!"&"E13")} -> 21204923 | J3: {=INDIRECT($A3&"!"&"F13")} -> 1844995.4 | K3: =H3-I3-J3 -> 2903553 | L3: =ABS((G3-B3)/B3) -> 0.039888248 | M3: =ABS((H3-C3)/C3) -> 0.037178294 | N3: =ABS((I3-D3)/D3) -> 0.023172537 | O3: =ABS((J3-E3)/E3) -> 0.019156987
A4: 202602 | B4: ='Task 4 - Forecasting'!O4 -> 32769.27 | C4: ='Task 4 - Forecasting'!$O4*'Task 4 - Forecasting'!P4 -> 22842718 | D4: ='Task 4 - Forecasting'!$O4*'Task 4 - Forecasting'!Q4 -> 20582140 | E4: ='Task 4 - Forecasting'!$O4*'Task 4 - Forecasting'!R4 -> 1766471.7 | F4: =C4-D4-E4 -> 494106.44 | G4: {=INDIRECT($A4&"!"&"C13")} -> 32491.007 | H4: {=INDIRECT($A4&"!"&"D13")} -> 26226665 | I4: {=INDIRECT($A4&"!"&"E13")} -> 23213810 | J4: {=INDIRECT($A4&"!"&"F13")} -> 1938254.7 | K4: =H4-I4-J4 -> 1074600.8 | L4: =ABS((G4-B4)/B4) -> 0.0084915599 | M4: =ABS((H4-C4)/C4) -> 0.14814119 | N4: =ABS((I4-D4)/D4) -> 0.12786183 | O4: =ABS((J4-E4)/E4) -> 0.097246418
A5: 202603 | B5: ='Task 4 - Forecasting'!O5 -> 33060.558 | C5: ='Task 4 - Forecasting'!$O5*'Task 4 - Forecasting'!P5 -> 24815792 | D5: ='Task 4 - Forecasting'!$O5*'Task 4 - Forecasting'!Q5 -> 22963239 | E5: ='Task 4 - Forecasting'!$O5*'Task 4 - Forecasting'!R5 -> 1835181.2 | F5: =C5-D5-E5 -> 17372.237 | G5: {=INDIRECT($A5&"!"&"C13")} -> 34155.898 | H5: {=INDIRECT($A5&"!"&"D13")} -> 25995101 | I5: {=INDIRECT($A5&"!"&"E13")} -> 23004551 | J5: {=INDIRECT($A5&"!"&"F13")} -> 1827881.9 | K5: =H5-I5-J5 -> 1162667.9 | L5: =ABS((G5-B5)/B5) -> 0.033131322 | M5: =ABS((H5-C5)/C5) -> 0.047522499 | N5: =ABS((I5-D5)/D5) -> 0.001799053 | O5: =ABS((J5-E5)/E5) -> 0.003977427
A6: 202604 | B6: ='Task 4 - Forecasting'!O6 -> 33383.362 | C6: ='Task 4 - Forecasting'!$O6*'Task 4 - Forecasting'!P6 -> 25506182 | D6: ='Task 4 - Forecasting'!$O6*'Task 4 - Forecasting'!Q6 -> 21878316 | E6: ='Task 4 - Forecasting'!$O6*'Task 4 - Forecasting'!R6 -> 1726491.4 | F6: =C6-D6-E6 -> 1901374.9 | G6: {=INDIRECT($A6&"!"&"C13")} -> 32497.845 | H6: {=INDIRECT($A6&"!"&"D13")} -> 26008110 | I6: {=INDIRECT($A6&"!"&"E13")} -> 21646692 | J6: {=INDIRECT($A6&"!"&"F13")} -> 1903258.4 | K6: =H6-I6-J6 -> 2458159.7 | L6: =ABS((G6-B6)/B6) -> 0.026525696 | M6: =ABS((H6-C6)/C6) -> 0.01967867 | N6: =ABS((I6-D6)/D6) -> 0.010586926 | O6: =ABS((J6-E6)/E6) -> 0.10238512
A7: 202605 | B7: ='Task 4 - Forecasting'!O7 -> 33722.238 | C7: ='Task 4 - Forecasting'!$O7*'Task 4 - Forecasting'!P7 -> 26670307 | D7: ='Task 4 - Forecasting'!$O7*'Task 4 - Forecasting'!Q7 -> 23570967 | E7: ='Task 4 - Forecasting'!$O7*'Task 4 - Forecasting'!R7 -> 1933932.7 | F7: =C7-D7-E7 -> 1165408.1 | G7: {=INDIRECT($A7&"!"&"C13")} -> 33167.903 | H7: {=INDIRECT($A7&"!"&"D13")} -> 24985582 | I7: {=INDIRECT($A7&"!"&"E13")} -> 23478871 | J7: {=INDIRECT($A7&"!"&"F13")} -> 1903643 | K7: =H7-I7-J7 -> -396932.35 | L7: =ABS((G7-B7)/B7) -> 0.016438261 | M7: =ABS((H7-C7)/C7) -> 0.063168575 | N7: =ABS((I7-D7)/D7) -> 0.0039071436 | O7: =ABS((J7-E7)/E7) -> 0.015662215
A8: 202606 | B8: ='Task 4 - Forecasting'!O8 -> 34051.746 | C8: ='Task 4 - Forecasting'!$O8*'Task 4 - Forecasting'!P8 -> 24867272 | D8: ='Task 4 - Forecasting'!$O8*'Task 4 - Forecasting'!Q8 -> 23180714 | E8: ='Task 4 - Forecasting'!$O8*'Task 4 - Forecasting'!R8 -> 1885746.7 | F8: =C8-D8-E8 -> -199188.46 | G8: {=INDIRECT($A8&"!"&"C13")} -> 33502.933 | H8: {=INDIRECT($A8&"!"&"D13")} -> 25237962 | I8: {=INDIRECT($A8&"!"&"E13")} -> 23018501 | J8: {=INDIRECT($A8&"!"&"F13")} -> 1999786.6 | K8: =H8-I8-J8 -> 219673.71 | L8: =ABS((G8-B8)/B8) -> 0.016117037 | M8: =ABS((H8-C8)/C8) -> 0.014906737 | N8: =ABS((I8-D8)/D8) -> 0.0069977225 | O8: =ABS((J8-E8)/E8) -> 0.060474665
A9: 202607 | B9: ='Task 4 - Forecasting'!O9 -> 34374.535 | C9: ='Task 4 - Forecasting'!$O9*'Task 4 - Forecasting'!P9 -> 27284220 | D9: ='Task 4 - Forecasting'!$O9*'Task 4 - Forecasting'!Q9 -> 23328360 | E9: ='Task 4 - Forecasting'!$O9*'Task 4 - Forecasting'!R9 -> 2149714.4 | F9: =C9-D9-E9 -> 1806145.6 | G9: {=INDIRECT($A9&"!"&"C13")} -> 33147.391 | H9: {=INDIRECT($A9&"!"&"D13")} -> 26278702 | I9: {=INDIRECT($A9&"!"&"E13")} -> 24188027 | J9: {=INDIRECT($A9&"!"&"F13")} -> 1903258.4 | K9: =H9-I9-J9 -> 187416.68 | L9: =ABS((G9-B9)/B9) -> 0.035699219 | M9: =ABS((H9-C9)/C9) -> 0.036853441 | N9: =ABS((I9-D9)/D9) -> 0.036850747 | O9: =ABS((J9-E9)/E9) -> 0.11464591
A10: 202608 | B10: ='Task 4 - Forecasting'!O10 -> 34692.979 | C10: ='Task 4 - Forecasting'!$O10*'Task 4 - Forecasting'!P10 -> 27322101 | D10: ='Task 4 - Forecasting'!$O10*'Task 4 - Forecasting'!Q10 -> 24484060 | E10: ='Task 4 - Forecasting'!$O10*'Task 4 - Forecasting'!R10 -> 1915297.3 | F10: =C10-D10-E10 -> 922743.73 | G10: {=INDIRECT($A10&"!"&"C13")} -> 34870.399 | H10: {=INDIRECT($A10&"!"&"D13")} -> 25211943 | I10: {=INDIRECT($A10&"!"&"E13")} -> 24427513 | J10: {=INDIRECT($A10&"!"&"F13")} -> 1980942.5 | K10: =H10-I10-J10 -> -1196512 | L10: =ABS((G10-B10)/B10) -> 0.0051140226 | M10: =ABS((H10-C10)/C10) -> 0.077232643 | N10: =ABS((I10-D10)/D10) -> 0.002309564 | O10: =ABS((J10-E10)/E10) -> 0.034274107
A11: 202609 | B11: ='Task 4 - Forecasting'!O11 -> 34978.522 | C11: ='Task 4 - Forecasting'!$O11*'Task 4 - Forecasting'!P11 -> 25675834 | D11: ='Task 4 - Forecasting'!$O11*'Task 4 - Forecasting'!Q11 -> 23624870 | E11: ='Task 4 - Forecasting'!$O11*'Task 4 - Forecasting'!R11 -> 1913107.6 | F11: =C11-D11-E11 -> 137856.11 | G11: {=INDIRECT($A11&"!"&"C13")} -> 33451.653 | H11: {=INDIRECT($A11&"!"&"D13")} -> 26263091 | I11: {=INDIRECT($A11&"!"&"E13")} -> 23948542 | J11: {=INDIRECT($A11&"!"&"F13")} -> 1980557.9 | K11: =H11-I11-J11 -> 333991.55 | L11: =ABS((G11-B11)/B11) -> 0.043651623 | M11: =ABS((H11-C11)/C11) -> 0.022871979 | N11: =ABS((I11-D11)/D11) -> 0.013700453 | O11: =ABS((J11-E11)/E11) -> 0.035256918
A12: 202610 | B12: ='Task 4 - Forecasting'!O12 -> 35256.494 | C12: ='Task 4 - Forecasting'!$O12*'Task 4 - Forecasting'!P12 -> 27593172 | D12: ='Task 4 - Forecasting'!$O12*'Task 4 - Forecasting'!Q12 -> 24032013 | E12: ='Task 4 - Forecasting'!$O12*'Task 4 - Forecasting'!R12 -> 2094600.8 | F12: =C12-D12-E12 -> 1466557.6 | G12: {=INDIRECT($A12&"!"&"C13")} -> 35909.674 | H12: {=INDIRECT($A12&"!"&"D13")} -> 27329851 | I12: {=INDIRECT($A12&"!"&"E13")} -> 24906484 | J12: {=INDIRECT($A12&"!"&"F13")} -> 2079778.1 | K12: =H12-I12-J12 -> 343588.9 | L12: =ABS((G12-B12)/B12) -> 0.01852653 | M12: =ABS((H12-C12)/C12) -> 0.0095429864 | N12: =ABS((I12-D12)/D12) -> 0.036387719 | O12: =ABS((J12-E12)/E12) -> 0.0070766203
A13: 202611 | B13: ='Task 4 - Forecasting'!O13 -> 35568.598 | C13: ='Task 4 - Forecasting'!$O13*'Task 4 - Forecasting'!P13 -> 27246821 | D13: ='Task 4 - Forecasting'!$O13*'Task 4 - Forecasting'!Q13 -> 24547848 | E13: ='Task 4 - Forecasting'!$O13*'Task 4 - Forecasting'!R13 -> 1991064.9 | F13: =C13-D13-E13 -> 707908.02 | G13: {=INDIRECT($A13&"!"&"C13")} -> 36613.919 | H13: {=INDIRECT($A13&"!"&"D13")} -> 28685415 | I13: {=INDIRECT($A13&"!"&"E13")} -> 23437020 | J13: {=INDIRECT($A13&"!"&"F13")} -> 1958444.9 | K13: =H13-I13-J13 -> 3289950.8 | L13: =ABS((G13-B13)/B13) -> 0.029388892 | M13: =ABS((H13-C13)/C13) -> 0.052798597 | N13: =ABS((I13-D13)/D13) -> 0.045251574 | O13: =ABS((J13-E13)/E13) -> 0.016383219
A14: 202612 | B14: ='Task 4 - Forecasting'!O14 -> 35908.139 | C14: ='Task 4 - Forecasting'!$O14*'Task 4 - Forecasting'!P14 -> 27374634 | D14: ='Task 4 - Forecasting'!$O14*'Task 4 - Forecasting'!Q14 -> 25111661 | E14: ='Task 4 - Forecasting'!$O14*'Task 4 - Forecasting'!R14 -> 1981821.8 | F14: =C14-D14-E14 -> 281151.85 | G14: {=INDIRECT($A14&"!"&"C13")} -> 35513.109 | H14: {=INDIRECT($A14&"!"&"D13")} -> 28682813 | I14: {=INDIRECT($A14&"!"&"E13")} -> 25385454 | J14: {=INDIRECT($A14&"!"&"F13")} -> 2099391.4 | K14: =H14-I14-J14 -> 1197967.7 | L14: =ABS((G14-B14)/B14) -> 0.011001136 | M14: =ABS((H14-C14)/C14) -> 0.047788005 | N14: =ABS((I14-D14)/D14) -> 0.010903054 | O14: =ABS((J14-E14)/E14) -> 0.059323965
A15: Totals | C15: =SUM(C3:C14) -> 3.1222221e+08 | D15: =SUM(D3:D14) -> 2.7901214e+08 | E15: =SUM(E3:E14) -> 23074461 | F15: =SUM(F3:F14) -> 10135608 | H15: =SUM(H3:H14) -> 3.1685871e+08 | I15: =SUM(I3:I14) -> 2.8186039e+08 | J15: =SUM(J3:J14) -> 23420193 | K15: =SUM(K3:K14) -> 11578126 | M15: =ABS((H15-C15)/C15) -> 0.01485 | N15: =ABS((I15-D15)/D15) -> 0.010208333 | O15: =ABS((J15-E15)/E15) -> 0.014983333

Sheet Trend Factors Table
B1: TREND FACTORS
A2: YYYYMM | B2: Members | C2: Prem/Mem | D2: Claims/Mem | E2: Exp/Mem
A3: 202501 | B3: 1.01 | C3: 1.03 | D3: 1.03 | E3: 1.03
A4: 202502 | B4: 1.01 | C4: 1.03 | D4: 1.03 | E4: 1.02
A5: 202503 | B5: 1.01 | C5: 1.04 | D5: 1.03 | E5: 1.01
A6: 202504 | B6: 1.01 | C6: 1.05 | D6: 1.01 | E6: 1.03
A7: 202505 | B7: 1.01 | C7: 1.05 | D7: 1.03 | E7: 1.02
A8: 202506 | B8: 1.01 | C8: 1.05 | D8: 1.03 | E8: 1.02
A9: 202507 | B9: 1.01 | C9: 1.05 | D9: 1.01 | E9: 1.03
A10: 202508 | B10: 1.01 | C10: 1.04 | D10: 1.03 | E10: 1.01
A11: 202509 | B11: 1.01 | C11: 1.05 | D11: 1.03 | E11: 1.03
A12: 202510 | B12: 1.01 | C12: 1.03 | D12: 1.01 | E12: 1.01
A13: 202511 | B13: 1.01 | C13: 1.04 | D13: 1.03 | E13: 1.03
A14: 202512 | B14: 1.01 | C14: 1.04 | D14: 1.02 | E14: 1.02

Sheet Base Data
A1: JANUARY FINANCIAL DATA
B2: Date | C2: Members | D2: Premiums | E2: Claims | F2: Expenses
B3: 46023 | D3: XXXXXX | E3: XXXXXX | F3: XXXXXX
B4: =B3+3 -> 46026 | D4: XXXXXX | E4: XXXXXX | F4: XXXXXX
B5: =B4+3 -> 46029 | D5: XXXXXX | E5: XXXXXX | F5: XXXXXX
B6: =B5+3 -> 46032 | D6: XXXXXX | E6: XXXXXX | F6: XXXXXX
B7: =B6+3 -> 46035 | D7: XXXXXX | E7: XXXXXX | F7: XXXXXX
B8: =B7+3 -> 46038 | D8: XXXXXX | E8: XXXXXX | F8: XXXXXX
B9: =B8+3 -> 46041 | D9: XXXXXX | E9: XXXXXX | F9: XXXXXX
B10: =B9+3 -> 46044 | D10: XXXXXX | E10: XXXXXX | F10: XXXXXX
B11: =B10+3 -> 46047 | D11: XXXXXX | E11: XXXXXX | F11: XXXXXX
B12: =B11+3 -> 46050 | D12: XXXXXX | E12: XXXXXX | F12: XXXXXX
B13: Totals | C13: =AVERAGE('Task 5 - Projected vs. Actual'!B3:B14)*RANDBETWEEN(95,105)/100*(1-(6-MONTH(B3))/100) -> 31503.013 | D13: =AVERAGE('Task 5 - Projected vs. Actual'!C3:C14)*RANDBETWEEN(95,105)/100*(1-(6-MONTH(B3))/100) -> 25211943 | E13: =AVERAGE('Task 5 - Projected vs. Actual'!D3:D14)*RANDBETWEEN(95,105)/100*(1-(6-MONTH(B3))/100) -> 22088461 | F13: =AVERAGE('Task 5 - Projected vs. Actual'!E3:E14)*RANDBETWEEN(95,105)/100*(1-(6-MONTH(B3))/100) -> 1881530

Sheet 202601
A1: JANUARY FINANCIAL DATA
B2: Date | C2: Members | D2: Premiums | E2: Claims | F2: Expenses
B3: 46023 | D3: XXXXXX | E3: XXXXXX | F3: XXXXXX
B4: 46026 | D4: XXXXXX | E4: XXXXXX | F4: XXXXXX
B5: 46029 | D5: XXXXXX | E5: XXXXXX | F5: XXXXXX
B6: 46032 | D6: XXXXXX | E6: XXXXXX | F6: XXXXXX
B7: 46035 | D7: XXXXXX | E7: XXXXXX | F7: XXXXXX
B8: 46038 | D8: XXXXXX | E8: XXXXXX | F8: XXXXXX
B9: 46041 | D9: XXXXXX | E9: XXXXXX | F9: XXXXXX
B10: 46044 | D10: XXXXXX | E10: XXXXXX | F10: XXXXXX
B11: 46047 | D11: XXXXXX | E11: XXXXXX | F11: XXXXXX
B12: 46050 | D12: XXXXXX | E12: XXXXXX | F12: XXXXXX
B13: Totals | C13: 31178.239 | D13: 25953471 | E13: 21204923 | F13: 1844995.4

Sheet 202602
A1: FEBRUARY FINANCIAL DATA
B2: Date | C2: Members | D2: Premiums | E2: Claims | F2: Expenses
B3: 46054 | D3: XXXXXX | E3: XXXXXX | F3: XXXXXX
B4: 46057 | D4: XXXXXX | E4: XXXXXX | F4: XXXXXX
B5: 46060 | D5: XXXXXX | E5: XXXXXX | F5: XXXXXX
B6: 46063 | D6: XXXXXX | E6: XXXXXX | F6: XXXXXX
B7: 46066 | D7: XXXXXX | E7: XXXXXX | F7: XXXXXX
B8: 46069 | D8: XXXXXX | E8: XXXXXX | F8: XXXXXX
B9: 46072 | D9: XXXXXX | E9: XXXXXX | F9: XXXXXX
B10: 46075 | D10: XXXXXX | E10: XXXXXX | F10: XXXXXX
B11: 46078 | D11: XXXXXX | E11: XXXXXX | F11: XXXXXX
B12: 46081 | D12: XXXXXX | E12: XXXXXX | F12: XXXXXX
B13: Totals | C13: 32491.007 | D13: 26226665 | E13: 23213810 | F13: 1938254.7

Sheet 202603
A1: MARCH FINANCIAL DATA
B2: Date | C2: Members | D2: Premiums | E2: Claims | F2: Expenses
B3: 46082 | D3: XXXXXX | E3: XXXXXX | F3: XXXXXX
B4: 46085 | D4: XXXXXX | E4: XXXXXX | F4: XXXXXX
B5: 46088 | D5: XXXXXX | E5: XXXXXX | F5: XXXXXX
B6: 46091 | D6: XXXXXX | E6: XXXXXX | F6: XXXXXX
B7: 46094 | D7: XXXXXX | E7: XXXXXX | F7: XXXXXX
B8: 46097 | D8: XXXXXX | E8: XXXXXX | F8: XXXXXX
B9: 46100 | D9: XXXXXX | E9: XXXXXX | F9: XXXXXX
B10: 46103 | D10: XXXXXX | E10: XXXXXX | F10: XXXXXX
B11: 46106 | D11: XXXXXX | E11: XXXXXX | F11: XXXXXX
B12: 46109 | D12: XXXXXX | E12: XXXXXX | F12: XXXXXX
B13: Totals | C13: 34155.898 | D13: 25995101 | E13: 23004551 | F13: 1827881.9

Sheet 202604
A1: APRIL FINANCIAL DATA
B2: Date | C2: Members | D2: Premiums | E2: Claims | F2: Expenses
B3: 46113 | D3: XXXXXX | E3: XXXXXX | F3: XXXXXX
B4: 46116 | D4: XXXXXX | E4: XXXXXX | F4: XXXXXX
B5: 46119 | D5: XXXXXX | E5: XXXXXX | F5: XXXXXX
B6: 46122 | D6: XXXXXX | E6: XXXXXX | F6: XXXXXX
B7: 46125 | D7: XXXXXX | E7: XXXXXX | F7: XXXXXX
B8: 46128 | D8: XXXXXX | E8: XXXXXX | F8: XXXXXX
B9: 46131 | D9: XXXXXX | E9: XXXXXX | F9: XXXXXX
B10: 46134 | D10: XXXXXX | E10: XXXXXX | F10: XXXXXX
B11: 46137 | D11: XXXXXX | E11: XXXXXX | F11: XXXXXX
B12: 46140 | D12: XXXXXX | E12: XXXXXX | F12: XXXXXX
B13: Totals | C13: 32497.845 | D13: 26008110 | E13: 21646692 | F13: 1903258.4

Sheet 202605
A1: MAY FINANCIAL DATA
B2: Date | C2: Members | D2: Premiums | E2: Claims | F2: Expenses
B3: 46143 | D3: XXXXXX | E3: XXXXXX | F3: XXXXXX
B4: 46146 | D4: XXXXXX | E4: XXXXXX | F4: XXXXXX
B5: 46149 | D5: XXXXXX | E5: XXXXXX | F5: XXXXXX
B6: 46152 | D6: XXXXXX | E6: XXXXXX | F6: XXXXXX
B7: 46155 | D7: XXXXXX | E7: XXXXXX | F7: XXXXXX
B8: 46158 | D8: XXXXXX | E8: XXXXXX | F8: XXXXXX
B9: 46161 | D9: XXXXXX | E9: XXXXXX | F9: XXXXXX
B10: 46164 | D10: XXXXXX | E10: XXXXXX | F10: XXXXXX
B11: 46167 | D11: XXXXXX | E11: XXXXXX | F11: XXXXXX
B12: 46170 | D12: XXXXXX | E12: XXXXXX | F12: XXXXXX
B13: Totals | C13: 33167.903 | D13: 24985582 | E13: 23478871 | F13: 1903643

Sheet 202606
A1: JUNE FINANCIAL DATA
B2: Date | C2: Members | D2: Premiums | E2: Claims | F2: Expenses
B3: 46174 | D3: XXXXXX | E3: XXXXXX | F3: XXXXXX
B4: 46177 | D4: XXXXXX | E4: XXXXXX | F4: XXXXXX
B5: 46180 | D5: XXXXXX | E5: XXXXXX | F5: XXXXXX
B6: 46183 | D6: XXXXXX | E6: XXXXXX | F6: XXXXXX
B7: 46186 | D7: XXXXXX | E7: XXXXXX | F7: XXXXXX
B8: 46189 | D8: XXXXXX | E8: XXXXXX | F8: XXXXXX
B9: 46192 | D9: XXXXXX | E9: XXXXXX | F9: XXXXXX
B10: 46195 | D10: XXXXXX | E10: XXXXXX | F10: XXXXXX
B11: 46198 | D11: XXXXXX | E11: XXXXXX | F11: XXXXXX
B12: 46201 | D12: XXXXXX | E12: XXXXXX | F12: XXXXXX
B13: Totals | C13: 33502.933 | D13: 25237962 | E13: 23018501 | F13: 1999786.6

Sheet 202607
A1: JULY FINANCIAL DATA
B2: Date | C2: Members | D2: Premiums | E2: Claims | F2: Expenses
B3: 46204 | D3: XXXXXX | E3: XXXXXX | F3: XXXXXX
B4: 46207 | D4: XXXXXX | E4: XXXXXX | F4: XXXXXX
B5: 46210 | D5: XXXXXX | E5: XXXXXX | F5: XXXXXX
B6: 46213 | D6: XXXXXX | E6: XXXXXX | F6: XXXXXX
B7: 46216 | D7: XXXXXX | E7: XXXXXX | F7: XXXXXX
B8: 46219 | D8: XXXXXX | E8: XXXXXX | F8: XXXXXX
B9: 46222 | D9: XXXXXX | E9: XXXXXX | F9: XXXXXX
B10: 46225 | D10: XXXXXX | E10: XXXXXX | F10: XXXXXX
B11: 46228 | D11: XXXXXX | E11: XXXXXX | F11: XXXXXX
B12: 46231 | D12: XXXXXX | E12: XXXXXX | F12: XXXXXX
B13: Totals | C13: 33147.391 | D13: 26278702 | E13: 24188027 | F13: 1903258.4

Sheet 202608
A1: AUGUST FINANCIAL DATA
B2: Date | C2: Members | D2: Premiums | E2: Claims | F2: Expenses
B3: 46235 | D3: XXXXXX | E3: XXXXXX | F3: XXXXXX
B4: 46238 | D4: XXXXXX | E4: XXXXXX | F4: XXXXXX
B5: 46241 | D5: XXXXXX | E5: XXXXXX | F5: XXXXXX
B6: 46244 | D6: XXXXXX | E6: XXXXXX | F6: XXXXXX
B7: 46247 | D7: XXXXXX | E7: XXXXXX | F7: XXXXXX
B8: 46250 | D8: XXXXXX | E8: XXXXXX | F8: XXXXXX
B9: 46253 | D9: XXXXXX | E9: XXXXXX | F9: XXXXXX
B10: 46256 | D10: XXXXXX | E10: XXXXXX | F10: XXXXXX
B11: 46259 | D11: XXXXXX | E11: XXXXXX | F11: XXXXXX
B12: 46262 | D12: XXXXXX | E12: XXXXXX | F12: XXXXXX
B13: Totals | C13: 34870.399 | D13: 25211943 | E13: 24427513 | F13: 1980942.5

Sheet 202609
A1: SEPTEMBER FINANCIAL DATA
B2: Date | C2: Members | D2: Premiums | E2: Claims | F2: Expenses
B3: 46266 | D3: XXXXXX | E3: XXXXXX | F3: XXXXXX
B4: 46269 | D4: XXXXXX | E4: XXXXXX | F4: XXXXXX
B5: 46272 | D5: XXXXXX | E5: XXXXXX | F5: XXXXXX
B6: 46275 | D6: XXXXXX | E6: XXXXXX | F6: XXXXXX
B7: 46278 | D7: XXXXXX | E7: XXXXXX | F7: XXXXXX
B8: 46281 | D8: XXXXXX | E8: XXXXXX | F8: XXXXXX
B9: 46284 | D9: XXXXXX | E9: XXXXXX | F9: XXXXXX
B10: 46287 | D10: XXXXXX | E10: XXXXXX | F10: XXXXXX
B11: 46290 | D11: XXXXXX | E11: XXXXXX | F11: XXXXXX
B12: 46293 | D12: XXXXXX | E12: XXXXXX | F12: XXXXXX
B13: Totals | C13: 33451.653 | D13: 26263091 | E13: 23948542 | F13: 1980557.9

Sheet 202610
A1: OCTOBER FINANCIAL DATA
B2: Date | C2: Members | D2: Premiums | E2: Claims | F2: Expenses
B3: 46296 | D3: XXXXXX | E3: XXXXXX | F3: XXXXXX
B4: 46299 | D4: XXXXXX | E4: XXXXXX | F4: XXXXXX
B5: 46302 | D5: XXXXXX | E5: XXXXXX | F5: XXXXXX
B6: 46305 | D6: XXXXXX | E6: XXXXXX | F6: XXXXXX
B7: 46308 | D7: XXXXXX | E7: XXXXXX | F7: XXXXXX
B8: 46311 | D8: XXXXXX | E8: XXXXXX | F8: XXXXXX
B9: 46314 | D9: XXXXXX | E9: XXXXXX | F9: XXXXXX
B10: 46317 | D10: XXXXXX | E10: XXXXXX | F10: XXXXXX
B11: 46320 | D11: XXXXXX | E11: XXXXXX | F11: XXXXXX
B12: 46323 | D12: XXXXXX | E12: XXXXXX | F12: XXXXXX
B13: Totals | C13: 35909.674 | D13: 27329851 | E13: 24906484 | F13: 2079778.1

Sheet 202611
A1: NOVEMBER FINANCIAL DATA
B2: Date | C2: Members | D2: Premiums | E2: Claims | F2: Expenses
